<?xml version="1.0"?>
<robot name="denso" xmlns:xacro="http://www.ros.org/wiki/xacro">

  <!-- Import all Gazebo-customization elements, including Gazebo colors -->
  <xacro:include filename="$(find denso_description)/urdf/denso.gazebo" />
  <!-- Import Rviz colors -->
  <xacro:include filename="$(find denso_description)/urdf/materials.xacro" />
  
  <!-- Used for fixing robot to Gazebo 'base_link' -->
  <link name="world"/>

  <joint name="fixed" type="fixed">
    <parent link="world"/>
    <child link="BASE"/>
  </joint>  
  
  <link name="BASE">
    <visual>
      <origin xyz="0 0 0" rpy="0 -0 0"/>
      <geometry>
        <mesh filename="package://denso_description/meshes/denso/BASE_mesh.stl"/>
      </geometry>
    </visual>
    <collision>
      <origin xyz="0 0 0" rpy="0 -0 0"/>
      <geometry>
        <mesh filename="package://denso_description/meshes/denso/BASE_mesh.stl"/>
      </geometry>
    </collision>
    <inertial>
      <mass value="1000" />
      <origin xyz="0 0 0" rpy="0 -0 0"/>
      <inertia ixx="20" ixy="0" ixz="0" iyy="20" iyz="0" izz="20"/>
    </inertial>
  </link>
  <link name="link_1">
    <visual>
      <origin xyz="0 4.04121e-17 0.182" rpy="0 -0 0"/>
      <geometry>
        <mesh filename="package://denso_description/meshes/denso/J1_mesh.stl"/>
      </geometry>
    </visual>
    <collision>
      <origin xyz="0 4.04121e-17 0.182" rpy="0 -0 0"/>
      <geometry>
        <mesh filename="package://denso_description/meshes/denso/J1_mesh.stl"/>
      </geometry>
    </collision>
    <inertial>
      <mass value="4.327" />
      <origin xyz="0.013885 -0.005997 0.043991" rpy="0 -0 0"/>
      <inertia ixx="0.025492" ixy="0" ixz="0" iyy="0.032502" iyz="-3.26672e-18" izz="0.01779"/>
    </inertial>
  </link>
  <link name="link_2">
    <visual>
      <origin xyz="0 3.61933e-17 0.163" rpy="0 -0 0"/>
      <geometry>
        <mesh filename="package://denso_description/meshes/denso/J2_mesh.stl"/>
      </geometry>
    </visual>
    <collision>
      <origin xyz="0 3.61933e-17 0.163" rpy="0 -0 0"/>
      <geometry>
        <mesh filename="package://denso_description/meshes/denso/J2_mesh.stl"/>
      </geometry>
    </collision>
    <inertial>
      <mass value="9.475" />
      <origin xyz="0.015837 -0.073696 0.010087" rpy="0 -0 0"/>
      <inertia ixx="0.108024" ixy="0" ixz="0" iyy="0.025579" iyz="1.93827e-17" izz="0.112871"/>
    </inertial>
  </link>
  <link name="link_3">
    <visual>
      <origin xyz="0 6.77236e-17 0.305" rpy="0 -0 0"/>
      <geometry>
        <mesh filename="package://denso_description/meshes/denso/J3_mesh.stl"/>
      </geometry>
    </visual>
    <collision>
      <origin xyz="0 6.77236e-17 0.305" rpy="0 -0 0"/>
      <geometry>
        <mesh filename="package://denso_description/meshes/denso/J3_mesh.stl"/>
      </geometry>
    </collision>
    <inertial>
      <mass value="4.097" />
      <origin xyz="0.011544 -0.057408 0.006203" rpy="0 -0 0"/>
      <inertia ixx="0.015999" ixy="0" ixz="0" iyy="0.00638" iyz="2.33191e-18" izz="0.016882"/>
    </inertial>
  </link>
  <link name="link_4">
    <visual>
      <origin xyz="-0.01 3.66374e-17 0.165" rpy="0 -0 0"/>
      <geometry>
        <mesh filename="package://denso_description/meshes/denso/J4_mesh.stl"/>
      </geometry>
    </visual>
    <collision>
      <origin xyz="-0.01 3.66374e-17 0.165" rpy="0 -0 0"/>
      <geometry>
        <mesh filename="package://denso_description/meshes/denso/J4_mesh.stl"/>
      </geometry>
    </collision>
    <inertial>
      <mass value="1.779" />
      <origin xyz="0.003998 -0.004975 0.052919" rpy="0 -0 0"/>
      <inertia ixx="0.005106" ixy="0" ixz="0" iyy="0.005266" iyz="-5.87308e-19" izz="0.002621"/>
    </inertial>
  </link>
  <link name="link_5">
    <visual>
      <origin xyz="0 2.9976e-17 0.135" rpy="0 -0 0"/>
      <geometry>
        <mesh filename="package://denso_description/meshes/denso/J5_mesh.stl"/>
      </geometry>
    </visual>
    <collision>
      <origin xyz="0 2.9976e-17 0.135" rpy="0 -0 0"/>
      <geometry>
        <mesh filename="package://denso_description/meshes/denso/J5_mesh.stl"/>
      </geometry>
    </collision>
    <inertial>
      <mass value="1.211" />
      <origin xyz="0.011902 -0.004739 0.010398" rpy="0 -0 0"/>
      <inertia ixx="0.001093" ixy="0" ixz="0" iyy="0.001629" iyz="-3.10862e-21" izz="0.001615"/>
    </inertial>
  </link>
  <link name="Flange">
    <visual>
      <origin xyz="0 1.55431e-17 0.07" rpy="0 -0 0"/>
      <geometry>
        <mesh filename="package://denso_description/meshes/denso/Flange_mesh.stl"/>
      </geometry>
    </visual>
    <collision>
      <origin xyz="0 1.55431e-17 0.07" rpy="0 -0 0"/>
      <geometry>
        <mesh filename="package://denso_description/meshes/denso/Flange_mesh.stl"/>
      </geometry>
    </collision>
    <inertial>
      <mass value="2.154" />
      <origin xyz="-0.000401015 0.0770342 0.0962886" rpy="0 -0 0"/>
      <inertia ixx="0.0216473" ixy="-0.000147026" ixz="-0.00011778" iyy="0.0346876" iyz="0.00159321" izz="0.022927"/>
    </inertial>
  </link>
  
  <!-- Camera -->
  <link name="camera_link">
    <collision>
      <origin xyz="0 0 0" rpy="0 0 0"/>
      <geometry>
	<box size="0.05 0.05 0.02"/>
      </geometry>
    </collision>

    <visual>
      <origin xyz="0 0 0" rpy="0 0 0"/>
      <geometry>
	<box size="0.05 0.05 0.02"/>
      </geometry>
      <material name="green"/>
    </visual>

    <inertial>
      <mass value="1e-5" />
      <origin xyz="0 0 0" rpy="0 0 0"/>
      <inertia ixx="1e-6" ixy="0" ixz="0" iyy="1e-6" iyz="0" izz="1e-6" />
    </inertial>
  </link>
  
  <joint name="j1" type="revolute">
    <parent link="BASE"/>
    <child  link="link_1"/>
    <origin xyz="0 4.04121e-17 0.182" rpy="0 -0 0 "/>
    <axis   xyz="0 0 1"/>
    <limit lower="-2.96706" upper="2.96706" effort="19.7336" velocity="0.5" />
  </joint>
  
  <joint name="j2" type="revolute">
    <parent link="link_1"/>
    <child  link="link_2"/>
    <origin xyz="0 3.61933e-17 0.163" rpy="0 -0 0 "/>
    <axis   xyz="0 1 0"/>
    <limit lower="-2.0944" upper="2.0944" effort="40.8447" velocity="0.5" />
  </joint>

  <joint name="j3" type="revolute">
    <parent link="link_2"/>
    <child  link="link_3"/>
    <origin xyz="0 6.77236e-17 0.305" rpy="0 -0 0 "/>
    <axis   xyz="0 1 0"/>
    <limit lower="-2.18166" upper="2.70526" effort="20.7089" velocity="0.5" />
  </joint>

  <joint name="j4" type="revolute">
    <parent link="link_3"/>
    <child  link="link_4"/>
    <origin xyz="-0.01 3.66374e-17 0.165" rpy="0 -0 0 "/>
    <axis   xyz="0 0 1"/>
    <limit lower="-4.71239" upper="4.71239" effort="20.9665" velocity="0.5" />
  </joint>

  <joint name="j5" type="revolute">
    <parent link="link_4"/>
    <child  link="link_5"/>
    <origin xyz="0 2.9976e-17 0.135" rpy="0 -0 0 "/>
    <axis   xyz="0 1 0"/>
    <limit lower="-2.0944" upper="2.0944" effort="23.7229" velocity="0.5" />
  </joint>

  <joint name="flange" type="revolute">
    <parent link="link_5"/>
    <child  link="Flange"/>
    <origin xyz="0 1.55431e-17 0.07" rpy="0 -0 0 "/>
    <axis   xyz="0 0 1"/>
    <limit lower="-6.28319" upper="6.28319" effort="33.5103" velocity="0.5" />
  </joint>  
  
  <joint name="camera_joint" type="fixed">
    <axis xyz="0 0 1" />
    <origin xyz="0 0 0" rpy="0 0 0"/>
    <parent link="Flange"/>
    <child link="camera_link"/>
  </joint>
  
  <transmission name="tran1">
    <type>transmission_interface/SimpleTransmission</type>
    <joint name="j1">
      <hardwareInterface>EffortJointInterface</hardwareInterface>
    </joint>
    <actuator name="motor1">
      <hardwareInterface>EffortJointInterface</hardwareInterface>
      <mechanicalReduction>1</mechanicalReduction>
    </actuator>
  </transmission>
  
  <transmission name="tran2">
    <type>transmission_interface/SimpleTransmission</type>
    <joint name="j2">
      <hardwareInterface>EffortJointInterface</hardwareInterface>
    </joint>
    <actuator name="motor2">
      <hardwareInterface>EffortJointInterface</hardwareInterface>
      <mechanicalReduction>50</mechanicalReduction>
    </actuator>
  </transmission>
  
  <transmission name="tran3">
    <type>transmission_interface/SimpleTransmission</type>
    <joint name="j3">
      <hardwareInterface>EffortJointInterface</hardwareInterface>
    </joint>
    <actuator name="motor3">
      <hardwareInterface>EffortJointInterface</hardwareInterface>
      <mechanicalReduction>50</mechanicalReduction>
    </actuator>
  </transmission>
  
  <transmission name="tran4">
    <type>transmission_interface/SimpleTransmission</type>
    <joint name="j4">
      <hardwareInterface>EffortJointInterface</hardwareInterface>
    </joint>
    <actuator name="motor4">
      <hardwareInterface>EffortJointInterface</hardwareInterface>
      <mechanicalReduction>50</mechanicalReduction>
    </actuator>
  </transmission>
  
  <transmission name="tran5">
    <type>transmission_interface/SimpleTransmission</type>
    <joint name="j5">
      <hardwareInterface>EffortJointInterface</hardwareInterface>
    </joint>
    <actuator name="motor5">
      <hardwareInterface>EffortJointInterface</hardwareInterface>
      <mechanicalReduction>50</mechanicalReduction>
    </actuator>
  </transmission>
  
  <transmission name="tran6">
    <type>transmission_interface/SimpleTransmission</type>
    <joint name="flange">
      <hardwareInterface>EffortJointInterface</hardwareInterface>
    </joint>
    <actuator name="motor_flange">
      <hardwareInterface>EffortJointInterface</hardwareInterface>
      <mechanicalReduction>50</mechanicalReduction>
    </actuator>
  </transmission>  
  
</robot>
